<?xml version="1.0" ?>
<robot name="ptbr" xmlns:xacro="http://www.ros.org/wiki/xacro">

<xacro:include filename="$(find ptbr)/urdf/materials.xacro" />
<xacro:include filename="$(find ptbr)/urdf/ptbr.ros2control" />
<xacro:include filename="$(find ptbr)/urdf/ptbr.gazebo" />
<link name="base_link">
  <inertial>
    <origin xyz="-0.00030771491577107806 0.006425674318858227 0.038113735190444614" rpy="0 0 0"/>
    <mass value="6.4013846052337655"/>
    <inertia ixx="0.018437" iyy="0.007171" izz="0.017545" ixy="0.0" iyz="-0.001397" ixz="-0.0"/>
  </inertial>
  <visual>
    <origin xyz="0 0 0" rpy="0 0 0"/>
    <geometry>
      <mesh filename="file://$(find ptbr)/meshes/base_link.stl" scale="0.001 0.001 0.001"/>
    </geometry>
    <material name="silver"/>
  </visual>
  <collision>
    <origin xyz="0 0 0" rpy="0 0 0"/>
    <geometry>
      <mesh filename="file://$(find ptbr)/meshes/base_link.stl" scale="0.001 0.001 0.001"/>
    </geometry>
  </collision>
</link>

<link name="head_1">
  <inertial>
    <origin xyz="2.850842288221471e-07 -0.001985837786485485 0.12158816571318953" rpy="0 0 0"/>
    <mass value="9.976187828305356"/>
    <inertia ixx="0.029478" iyy="0.029097" izz="0.015168" ixy="0.0" iyz="0.000325" ixz="-0.0"/>
  </inertial>
  <visual>
    <origin xyz="0.000308 -0.041636 -0.119416" rpy="0 0 0"/>
    <geometry>
      <mesh filename="file://$(find ptbr)/meshes/head_1.stl" scale="0.001 0.001 0.001"/>
    </geometry>
    <material name="silver"/>
  </visual>
  <collision>
    <origin xyz="0.000308 -0.041636 -0.119416" rpy="0 0 0"/>
    <geometry>
      <mesh filename="file://$(find ptbr)/meshes/head_1.stl" scale="0.001 0.001 0.001"/>
    </geometry>
  </collision>
</link>

<link name="right_wheel_1">
  <inertial>
    <origin xyz="-0.019999714915771002 -2.0220914574015092e-07 2.2264549151551627e-07" rpy="0 0 0"/>
    <mass value="1.1403478677706373"/>
    <inertia ixx="0.000659" iyy="0.000482" izz="0.000482" ixy="0.0" iyz="0.0" ixz="-0.0"/>
  </inertial>
  <visual>
    <origin xyz="0.040308 -0.002654 -0.028416" rpy="0 0 0"/>
    <geometry>
      <mesh filename="file://$(find ptbr)/meshes/right_wheel_1.stl" scale="0.001 0.001 0.001"/>
    </geometry>
    <material name="silver"/>
  </visual>
  <collision>
    <origin xyz="0.040308 -0.002654 -0.028416" rpy="0 0 0"/>
    <geometry>
      <mesh filename="file://$(find ptbr)/meshes/right_wheel_1.stl" scale="0.001 0.001 0.001"/>
    </geometry>
  </collision>
</link>

<link name="left_wheel_1">
  <inertial>
    <origin xyz="0.020000285084228846 -2.0220914535677703e-07 2.2264549146347457e-07" rpy="0 0 0"/>
    <mass value="1.1403478677706371"/>
    <inertia ixx="0.000659" iyy="0.000482" izz="0.000482" ixy="0.0" iyz="0.0" ixz="-0.0"/>
  </inertial>
  <visual>
    <origin xyz="-0.039692 -0.002654 -0.028416" rpy="0 0 0"/>
    <geometry>
      <mesh filename="file://$(find ptbr)/meshes/left_wheel_1.stl" scale="0.001 0.001 0.001"/>
    </geometry>
    <material name="silver"/>
  </visual>
  <collision>
    <origin xyz="-0.039692 -0.002654 -0.028416" rpy="0 0 0"/>
    <geometry>
      <mesh filename="file://$(find ptbr)/meshes/left_wheel_1.stl" scale="0.001 0.001 0.001"/>
    </geometry>
  </collision>
</link>

<link name="left_arm_1">
  <inertial>
    <origin xyz="0.018087977944126324 -0.005800896128886866 -0.056698307724850905" rpy="0 0 0"/>
    <mass value="1.013009141787747"/>
    <inertia ixx="0.002313" iyy="0.002182" izz="0.000268" ixy="8e-06" iyz="-0.00039" ixz="6.4e-05"/>
  </inertial>
  <visual>
    <origin xyz="-0.049692 -0.041636 -0.266278" rpy="0 0 0"/>
    <geometry>
      <mesh filename="file://$(find ptbr)/meshes/left_arm_1.stl" scale="0.001 0.001 0.001"/>
    </geometry>
    <material name="silver"/>
  </visual>
  <collision>
    <origin xyz="-0.049692 -0.041636 -0.266278" rpy="0 0 0"/>
    <geometry>
      <mesh filename="file://$(find ptbr)/meshes/left_arm_1.stl" scale="0.001 0.001 0.001"/>
    </geometry>
  </collision>
</link>

<link name="right_arm_1">
  <inertial>
    <origin xyz="-0.018087407770600646 -0.005810132869209922 -0.056697751450645734" rpy="0 0 0"/>
    <mass value="1.0130091381540007"/>
    <inertia ixx="0.002313" iyy="0.002182" izz="0.000268" ixy="-8e-06" iyz="-0.00039" ixz="-6.4e-05"/>
  </inertial>
  <visual>
    <origin xyz="0.050308 -0.041636 -0.266278" rpy="0 0 0"/>
    <geometry>
      <mesh filename="file://$(find ptbr)/meshes/right_arm_1.stl" scale="0.001 0.001 0.001"/>
    </geometry>
    <material name="silver"/>
  </visual>
  <collision>
    <origin xyz="0.050308 -0.041636 -0.266278" rpy="0 0 0"/>
    <geometry>
      <mesh filename="file://$(find ptbr)/meshes/right_arm_1.stl" scale="0.001 0.001 0.001"/>
    </geometry>
  </collision>
</link>

<joint name="head_to_base_link" type="revolute">
  <origin xyz="-0.000308 0.041636 0.119416" rpy="0 0 0"/>
  <parent link="base_link"/>
  <child link="head_1"/>
  <axis xyz="1.0 0.0 -0.0"/>
  <limit upper="0.785399" lower="-0.785399" effort="100" velocity="100"/>
</joint>

<joint name="right_wheel_to_base_link" type="continuous">
  <origin xyz="-0.040308 0.002654 0.028416" rpy="0 0 0"/>
  <parent link="base_link"/>
  <child link="right_wheel_1"/>
  <axis xyz="-1.0 -0.0 0.0"/>
</joint>

<joint name="left_wheel_to_base_link" type="continuous">
  <origin xyz="0.039692 0.002654 0.028416" rpy="0 0 0"/>
  <parent link="base_link"/>
  <child link="left_wheel_1"/>
  <axis xyz="1.0 0.0 -0.0"/>
</joint>

<joint name="left_arm_to_base_link" type="continuous">
  <origin xyz="0.05 0.0 0.146862" rpy="0 0 0"/>
  <parent link="head_1"/>
  <child link="left_arm_1"/>
  <axis xyz="1.0 0.0 -0.0"/>
</joint>

<joint name="right_arm_to_base_link" type="continuous">
  <origin xyz="-0.05 0.0 0.146862" rpy="0 0 0"/>
  <parent link="head_1"/>
  <child link="right_arm_1"/>
  <axis xyz="-1.0 -0.0 0.0"/>
</joint>

</robot>
