<?xml version="1.0" ?>
<robot name="ptbr" xmlns:xacro="http://www.ros.org/wiki/xacro">

<xacro:include filename="$(find ptbr)/urdf/materials.xacro" />
<xacro:include filename="$(find ptbr)/urdf/ptbr.ros2control" />
<xacro:include filename="$(find ptbr)/urdf/ptbr.gazebo" />

<xacro:include filename="$(find ptbr)/urdf/camera.xacro" />

<link name="base_footprint">
  
</link>

<joint name="base_link_joint" type="fixed">
  <origin xyz="0 0 0.0325"/>
  <parent link="base_footprint"/>
  <child link="base_link"/>
  
</joint>

<link name="base_link">
</link>

<joint name="base_joint" type="fixed">
  <parent link="base_link"/>
  <child link="base"/>
</joint>

<link name="base">
  <inertial>
    <origin xyz="0.006425674318858227 -0.00030771491577107806 0.038113735190444614" rpy="0 0 0"/>
    <mass value="10"/>
    <inertia ixx="0.018437" iyy="0.007171" izz="0.017545" ixy="0.0" iyz="-0.001397" ixz="-0.0"/>
  </inertial>
  <visual>
    <origin xyz="0 0 0.006" rpy="0 0 0"/>
    <geometry>
      <box size="0.1634 0.08 0.06"/>
    </geometry>
    <material name="silver"/>
  </visual>
  <visual>
    <origin xyz="-0.0327525 0.0 0.0575" rpy="0.0 0.0 0.0"/>
    <geometry>
      <box size="0.032895 0.032895 0.055"/>
    </geometry>
    <material name="silver"/>
  </visual>
  <collision>
    <origin xyz="0 0 0.006" rpy="0 0 0"/>
    <geometry>
      <box size="0.1634 0.08 0.06"/>
    </geometry>
    <material name="silver"/>
  </collision>
  <collision>
    <origin xyz="-0.0327525 0.0 0.0575" rpy="0.0 0.0 0.0"/>
    <geometry>
      <box size="0.032895 0.032895 0.055"/>
    </geometry>
    <material name="silver"/>
  </collision>
</link>

<joint name="head_joint" type="revolute">
  <origin xyz="-0.0327525 0 0.085" rpy="0 0 0"/>
  <parent link="base_link"/>
  <child link="head"/>
  <axis xyz="0.0 1.0 0.0"/>
  <limit upper="0.785399" lower="-0.785399" effort="100" velocity="100"/>
</joint>

<link name="head">
  <inertial>
    <origin xyz="2.850842288221471e-07 -0.001985837786485485 0.12158816571318953" rpy="0 0 0"/>
    <mass value="2"/>
    <inertia ixx="0.029478" iyy="0.029097" izz="0.015168" ixy="0.0" iyz="0.000325" ixz="-0.0"/>
  </inertial>
  <visual>
    <origin xyz="0 0 0.138" rpy="0 0 0"/>
    <geometry>
      <box size="0.1 0.1 0.1"/>
    </geometry>
    <material name="silver"/>
  </visual>

  <visual>
    <origin xyz="0.041 0 0.138" rpy="0.0 0.0 0.0"/>
    <geometry>
      <box size="0.018 0.106 0.106"/>
    </geometry>
  </visual>
  <visual>
    <origin xyz="0 0 0.024" rpy="0.0 0.0 0.0"/>
    <geometry>
      <box size="0.038895 0.038895 0.048"/>
    </geometry>
    <material name="silver"/>

  </visual>
  <visual>
    <origin xyz="0.0 0.0 0.068" rpy="0.0 0.0 0.0"/>
    <geometry>
      <box size="0.0525 0.0525 0.04"/>
    </geometry>
  </visual>
  <collision>
    <origin xyz="0 0 0.138" rpy="0 0 0"/>
    <geometry>
      <box size="0.1 0.1 0.1"/>
    </geometry>
  </collision>

  <collision>
    <origin xyz="0.041 0 0.138" rpy="0.0 0.0 0.0"/>
    <geometry>
      <box size="0.018 0.106 0.106"/>
    </geometry>
  </collision>
  <collision>
    <origin xyz="0 0 0.024" rpy="0.0 0.0 0.0"/>
    <geometry>
      <box size="0.038895 0.038895 0.048"/>
    </geometry>
  </collision>
  <collision>
    <origin xyz="0.0 0.0 0.068" rpy="0.0 0.0 0.0"/>
    <geometry>
      <box size="0.0525 0.0525 0.04"/>
    </geometry>
  </collision>
</link>




<joint name="right_wheel_joint" type="continuous">
  <origin xyz="0 -0.06 0" rpy="${pi/2} 0 0"/>
  <parent link="base_link"/>
  <child link="right_wheel"/>
  <axis xyz="0 0.0 -1"/>
  <limit effort="50000" velocity="10"/>
  <dynamics damping="1.0" friction="1.0"/>
</joint>

<link name="right_wheel">
  <inertial>
    <origin xyz="-0.019999714915771002 -2.0220914574015092e-07 2.2264549151551627e-07" rpy="0 0 0"/>
    <mass value="1"/>
    <inertia ixx="0.000659" iyy="0.000482" izz="0.000482" ixy="0.0" iyz="0.0" ixz="-0.0"/>
  </inertial>
  <visual>
    <origin xyz="0 0 0" rpy="0 0 0"/>
    <geometry>
      <cylinder radius="0.0325" length="0.04"/>
    </geometry>
    <material name="silver"/>
  </visual>
  <collision>
    <origin xyz="0 0 0" rpy="0 0 0"/>
    <geometry>
      <cylinder radius="0.0325" length="0.04"/>
    </geometry>
  </collision>
</link>

<joint name="left_wheel_joint" type="continuous">
  <origin xyz="0 0.06 0" rpy="-${pi/2} 0 0"/>
  <parent link="base_link"/>
  <child link="left_wheel"/>
  <axis xyz="0 0.0 1"/>
  <limit effort="50000" velocity="10"/>
  <dynamics damping="1.0" friction="1.0"/>
</joint>

<link name="left_wheel">
  <inertial>
    <origin xyz="-0.019999714915771002 -2.0220914574015092e-07 2.2264549151551627e-07" rpy="0 0 0"/>
    <mass value="1"/>
    <inertia ixx="0.000659" iyy="0.000482" izz="0.000482" ixy="0.0" iyz="0.0" ixz="-0.0"/>
  </inertial>
  <visual>
    <origin xyz="0 0 0" rpy="0 0 0"/>
    <geometry>
      <cylinder radius="0.0325" length="0.04"/>
    </geometry>
    <material name="silver"/>
  </visual>
  <collision>
    <origin xyz="0 0 0" rpy="0 0 0"/>
    <geometry>
      <cylinder radius="0.0325" length="0.04"/>
    </geometry>
  </collision>
</link>


<joint name="left_arm_joint" type="continuous">
  <origin xyz="0.0 0.05 0.146862" rpy="-${pi/2} 0 0"/>
  <parent link="head"/>
  <child link="left_arm"/>
  <axis xyz="0 0.0 -1"/>
</joint>

<link name="left_arm">
  <inertial>
    <origin xyz="0.018087977944126324 -0.005800896128886866 -0.056698307724850905" rpy="0 0 0"/>
    <mass value="0.1"/>
    <inertia ixx="0.002313" iyy="0.002182" izz="0.000268" ixy="8e-06" iyz="-0.00039" ixz="6.4e-05"/>
  </inertial>
  <visual>
    <origin xyz="0.041636 0.266278 -0.049692" rpy="-${pi/2} -${pi/2} ${pi}"/>
    <geometry>
      <mesh filename="package://ptbr/meshes/left_arm_1.stl" scale="0.001 0.001 0.001"/>
    </geometry>
    <material name="silver"/>
  </visual>
  <collision>
    <origin xyz="0.041636 0.266278 -0.049692" rpy="-${pi/2} -${pi/2} ${pi}"/>
    <geometry>
      <mesh filename="package://ptbr/meshes/left_arm_1.stl" scale="0.001 0.001 0.001"/>
    </geometry>
  </collision>
</link>

<joint name="right_arm_joint" type="continuous">
  <origin xyz="0.0 -0.05 0.146862" rpy="${pi/2} 0 0"/>
  <parent link="head"/>
  <child link="right_arm"/>
  <axis xyz="0 0.0 1"/>
</joint>

<link name="right_arm">
  <inertial>
    <origin xyz="-0.018087407770600646 -0.005810132869209922 -0.056697751450645734" rpy="0 0 0"/>
    <mass value="0.1"/>
    <inertia ixx="0.002313" iyy="0.002182" izz="0.000268" ixy="-8e-06" iyz="-0.00039" ixz="-6.4e-05"/>
  </inertial>
  <visual>
    <origin xyz="0.041636 -0.266278 -0.050308" rpy="${pi/2} ${pi/2} ${pi}"/>
    <geometry>
      <mesh filename="package://ptbr/meshes/right_arm_1.stl" scale="0.001 0.001 0.001"/>
    </geometry>
    <material name="silver"/>
  </visual>
  <collision>
    <origin xyz="0.041636 -0.266278 -0.050308" rpy="${pi/2} ${pi/2} ${pi}"/>
    <geometry>
      <mesh filename="package://ptbr/meshes/right_arm_1.stl" scale="0.001 0.001 0.001"/>
    </geometry>
  </collision>
</link>



</robot>
